Workbook
Name Slicer_ACCOUNT: #N/A

Sheet CHARTS OF ACCOUNTS
B3: ACCOUNTS RECEIVABLE | C3: CURRENT ASSET | E3: BALANCE SHEET
B4: ADVERTISMENT | C4: EXPENSE | E4: INCOME STATEMENT
B5: AHMED TRADERS | C5: CURRENT LIABILITY | E5: BALANCE SHEET
B6: ALLOWNCE FOR DEPRECIATION - FURNITURE | C6: CONTRA ASSETS | E6: BALANCE SHEET
B7: BANK | C7: CURRENT ASSET | E7: BALANCE SHEET
B8: BILAL STORES | C8: CURRENT ASSET | E8: BALANCE SHEET
B9: CAPITAL | C9: EQUITY | E9: BALANCE SHEET
B10: CASH | C10: CURRENT ASSET | E10: BALANCE SHEET
B11: DELIVERY | C11: EXPENSE | E11: INCOME STATEMENT
B12: DEPRECIATION | C12: EXPENSE | E12: INCOME STATEMENT
B13: ELECTRICITY | C13: EXPENSE | E13: INCOME STATEMENT
B14: FRIEGHT | C14: EXPENSE | E14: INCOME STATEMENT
... B26: INVENTORY RETURN | C26: CONTRA ASSETS | E26: BALANCE SHEET

Sheet Transactions
A1: TRANSACTIONS
A2: No. | B2: Date | C2: Description | D2: Amount (PKR) | E2: Mode/Ref | F2: REFRENCE | H2: BANK STATEMENT
A3: 1 | B3: 46082 | C3: Opening Inventory as at calculated on 1 march | D3: 56300
A4: 2 | B4: 46082 | C4: Owner introduced capital | D4: 550000 | E4: Cash | H4: Date | I4: Description / Particulars | J4: Debit (Payements) PKR | K4: Credit (Receipts) PKR | L4: Balance PKR
A5: 3 | B5: 46082 | C5: Paid shop rent | D5: 40000 | E5: Cash
A6: 4 | B6: 46083 | C6: Purchased goods from Ahmed Traders | D6: 85000 | E6: Credit | H6: 46082 | I6: Opening Balance (as per bank statement) | L6: 0
A7: 5 | B7: 46084 | C7: Cash sales | D7: 32000 | E7: Cash
A8: 6 | B8: 46085 | C8: Goods sold to Bilal Stores | D8: 60000 | E8: Credit | H8: 46088 | I8: Deposit from Bilal Stores | K8: 25000 | L8: =L6+K8-J8 -> 25000
A9: 7 | B9: 46086 | C9: Paid electricity bill | D9: 12500 | E9: Bank cheque CHQ-101 | H9: 46093 | I9: Deposit from Sana Mart | K9: 18000 | L9: =L8+K9-J9 -> 43000
A10: 8 | B10: 46087 | C10: Purchased office furniture | D10: 55000 | E10: Bank cheque CHQ-102 | H10: 46099 | I10: Deposit from Bilal Stores | K10: 24000 | L10: =L9+K10-J10 -> 67000
A11: 9 | B11: 46088 | C11: Received from Bilal Stores | D11: 25000 | E11: Bank deposit DEP-201 | H11: 46099 | I11: Dishonoured Cheque | J11: 24000 | L11: =L10+K11-J11 -> 43000
A12: 10 | B12: 46089 | C12: Purchased goods | D12: 42000 | E12: Cash | H12: 46102 | I12: Advertising cheque | J12: 9000 | L12: =L11+K12-J12 -> 34000
A13: 11 | B13: 46090 | C13: Freight inward paid | D13: 4500 | E13: Cash | H13: 46110 | I13: Bank service charges | J13: 500 | L13: =L12+K13-J13 -> 33500
A14: 12 | B14: 46091 | C14: Returned goods to Ahmed Traders | D14: 5000 | E14: Credit note | H14: 46112 | I14: Bank profit/interest credited | K14: 300 | L14: =L13+K14-J14 -> 33800
A15: 13 | B15: 46092 | C15: Sales to Sana Mart | D15: 48000 | E15: Credit | L15: Closing Balance
A16: 14 | B16: 46093 | C16: Received from Sana Mart | D16: 18000 | E16: Bank deposit DEP-202
A17: 15 | B17: 46094 | C17: Paid salaries | D17: 30000 | E17: Cash
A18: 16 | B18: 46095 | C18: Shop supplies purchased | D18: 6800 | E18: Cash
A19: 17 | B19: 46096 | C19: Paid Ahmed Traders | D19: 20000 | E19: Bank cheque CHQ-103
A20: 18 | B20: 46097 | C20: Credit sales to a customer | D20: 27500 | E20: Cash
A21: 19 | B21: 46098 | C21: Customer returned goods | D21: 3000 | E21: Cash refund
A22: 20 | B22: 46099 | C22: Received from Bilal Stores | D22: 24000 | E22: Bank deposit DEP-203
A23: 21 | B23: 46100 | C23: Water bill paid | D23: 3200 | E23: Cash
A24: 22 | B24: 46101 | C24: Purchased goods from Noor Wholesalers | D24: 70000 | E24: Credit
A25: 23 | B25: 46102 | C25: Advertising paid | D25: 9000 | E25: Bank cheque CHQ-104
A26: 24 | B26: 46103 | C26: Cheque received from Sana Mart | D26: 12000 | E26: Bank deposit DEP-204
A27: 25 | B27: 46104 | C27: Owner withdrew for personal use | D27: 10000 | E27: Cash
... A35: 33 | B35: 46112 | C35: Depreciation on furniture for the month | D35: 1500 | E35: Adjustment

Sheet GENERAL JOURNAL
A9: DATE | B9: DESCRIPTION | C9: ACCOUNT | D9: DEBIT | E9: CREDIT | F9: REFRENCE ID
A10: 46082 | B10: Owner introduced capital | C10: CASH | D10: 550000
B11: Owner introduced capital | C11: CAPITAL | E11: 550000
A12: 46082 | B12: Paid shop rent | C12: RENT | D12: 40000
B13: Paid shop rent | C13: CASH | E13: 40000
A14: 46083 | B14: Purchased goods from Ahmed Traders | C14: INVENTORY | D14: 85000
B15: Purchased goods from Ahmed Traders | C15: CASH | E15: 85000
A16: 46084 | B16: Cash sales | C16: CASH | D16: 32000
B17: Cash sales | C17: SALES | E17: 32000
A18: 46085 | B18: Goods sold to Bilal Stores | C18: BILAL STORES | D18: 60000
B19: Goods sold to Bilal Stores | C19: SALES | E19: 60000
A20: 46086 | B20: Paid electricity bill | C20: ELECTRICITY | D20: 12500
B21: Paid electricity bill | C21: CASH | E21: 12500
A22: 46087 | B22: Purchased office furniture | C22: OFFICE FURNITURE | D22: 55000
B23: Purchased office furniture | C23: CASH | E23: 55000
A24: 46088 | B24: Received from Bilal Stores | C24: BANK | D24: 25000
B25: Received from Bilal Stores | C25: BILAL STORES | E25: 25000
A26: 46089 | B26: Purchased goods | C26: INVENTORY | D26: 42000
B27: Purchased goods | C27: CASH | E27: 42000
A28: 46090 | B28: Freight inward paid | C28: FRIEGHT | D28: 4500
B29: Freight inward paid | C29: CASH | E29: 4500
A30: 46091 | B30: Returned goods to Ahmed Traders | C30: AHMED TRADERS | D30: 5000
B31: Returned goods to Ahmed Traders | C31: INVENTORY RETURN | E31: 5000
A32: 46092 | B32: Sales to Sana Mart on Credit | C32: SANA MART | D32: 48000
B33: Sales to Sana Mart on Credit | C33: SALES | E33: 48000
A34: 46093 | B34: Received from Sana Mart | C34: BANK | D34: 18000
B35: Received from Sana Mart | C35: SANA MART | E35: 18000
A36: 46094 | B36: Paid salaries | C36: SALARIES | D36: 30000
B37: Paid salaries | C37: CASH | E37: 30000
A38: 46095 | B38: Shop supplies purchased | C38: SUPPLIES | D38: 6800
B39: Shop supplies purchased | C39: CASH | E39: 6800
A40: 46096 | B40: Paid Ahmed Traders | C40: AHMED TRADERS | D40: 20000
B41: Paid Ahmed Traders | C41: CASH | E41: 20000
A42: 46097 | B42: Credit sales to a customer | C42: ACCOUNTS RECEIVABLE | D42: 275000
B43: Credit sales to a customer | C43: SALES | E43: 275000
A44: 46098 | B44: Customer returned goods | C44: SALES RETURN | D44: 3000
B45: Customer returned goods | C45: CASH | E45: 3000
A46: 46099 | B46: Received from Bilal Stores | C46: BANK | D46: 24000
B47: Received from Bilal Stores | C47: BILAL STORES | E47: 24000
A48: 46100 | B48: Water bill paid | C48: WATER | D48: 3200
...

Sheet GENERAL LEDGER
B9: ACCOUNT | C9: DESCRIPTION | D9: Sum of DEBIT | E9: Sum of CREDIT | F9: Sum of BALANCE
B10: ACCOUNTS RECEIVABLE | D10: 275000 | E10: 12000 | F10: 263000
B11: ADVERTISMENT | D11: 9000 | F11: 9000
B12: AHMED TRADERS | D12: 25000 | F12: 25000
B13: ALLOWNCE FOR DEPRECIATION - FURNITURE | E13: 1500 | F13: -1500
B14: BANK | D14: 100000 | E14: 13000 | F14: 87000
B15: BILAL STORES | D15: 60000 | E15: 58000 | F15: 2000
B16: CAPITAL | D16: 10000 | E16: 550000 | F16: -540000
B17: CASH | D17: 947000 | E17: 360500 | F17: 586500
B18: DELIVERY | D18: 4000 | F18: 4000
B19: DEPRECIATION | D19: 1500 | F19: 1500
B20: ELECTRICITY | D20: 12500 | F20: 12500
B21: FRIEGHT | D21: 4500 | F21: 4500
B22: INVENTORY | D22: 225000 | F22: 225000
B23: INVENTORY RETURN | E23: 5000 | F23: -5000
B24: NOOR WHOLESALERS | D24: 15000 | E24: 70000 | F24: -55000
B25: OFFICE FURNITURE | D25: 55000 | F25: 55000
B26: RENT | D26: 40000 | F26: 40000
B27: SALARIES | D27: 30000 | F27: 30000
B28: SALES | E28: 780000 | F28: -780000
B29: SALES RETURN | D29: 3000 | F29: 3000
B30: SANA MART | D30: 48000 | E30: 30000 | F30: 18000
B31: SUPPLIES | D31: 6800 | F31: 6800
B32: TELEPHONE AND INTERNET | D32: 5500 | F32: 5500
B33: WATER | D33: 3200 | F33: 3200
B34: Grand Total | D34: 1880000 | E34: 1880000 | F34: 0

Sheet TRIAL BALANCE
B9: Row Labels | C9: Sum of DEBIT | D9: Sum of CREDIT
B10: ACCOUNTS RECEIVABLE | C10: 275000 | D10: 12000
B11: ADVERTISMENT | C11: 9000
B12: AHMED TRADERS | C12: 25000
B13: ALLOWNCE FOR DEPRECIATION - FURNITURE | D13: 1500
B14: BANK | C14: 100000 | D14: 13000
B15: BILAL STORES | C15: 60000 | D15: 58000
B16: CAPITAL | C16: 10000 | D16: 550000
B17: CASH | C17: 947000 | D17: 360500
B18: DELIVERY | C18: 4000
B19: DEPRECIATION | C19: 1500
B20: ELECTRICITY | C20: 12500
B21: FRIEGHT | C21: 4500
B22: INVENTORY | C22: 225000
B23: NOOR WHOLESALERS | C23: 15000 | D23: 70000
B24: OFFICE FURNITURE | C24: 55000
B25: RENT | C25: 40000
B26: SALARIES | C26: 30000
B27: SALES | D27: 780000
B28: SALES RETURN | C28: 3000
B29: SANA MART | C29: 48000 | D29: 30000
B30: SUPPLIES | C30: 6800
B31: WATER | C31: 3200
B32: INVENTORY RETURN | D32: 5000
B33: TELEPHONE AND INTERNET | C33: 5500
B34: Grand Total | C34: 1880000 | D34: 1880000

Sheet CASH BOOK
B6: RECEIPTS | G6: PAYAMENTS
B7: CASH TOTAL | E7: =SUM(Table3[CASH]) -> 1894000 | G7: CASH TOTAL | J7: =SUM(Table3[[CASH ]]) -> 1307500
B8: BANK TOTAL | E8: =SUM(Table3[BANK]) -> 200000 | G8: BANK TOTAL | J8: =SUM(Table3[[BANK ]]) -> 113000
B9: GRAND TOTAL | E9: =SUM(E7:E8) -> 2094000 | G9: GRAND TOTAL | J9: =SUM(J7:J8) -> 1420500
B11: RECEIPTS | G11: PAYAMENTS
B12: DATE | C12: PARTICULERS | D12: CASH | E12: BANK | G12: DATE | H12: PARTICULERS | I12: CASH | J12: BANK
B13: 46082 | C13: To opening balance | D13: 0
B14: 46082 | C14: Owner introduced capital | D14: 550000 | G14: 46082 | H14: Paid shop rent | I14: 40000
B15: 46084 | C15: Cash sales | D15: 32000 | G15: 46083 | H15: Purchased goods from Ahmed Traders | I15: 85000
B16: 46088 | C16: Received from Bilal Stores | E16: 25000 | G16: 46086 | H16: Paid electricity bill | I16: 12500
B17: 46093 | C17: Received from Sana Mart | E17: 18000 | G17: 46087 | H17: Purchased office furniture | I17: 55000
B18: 46099 | C18: Received from Bilal Stores | E18: 24000 | G18: 46089 | H18: Purchased goods | I18: 42000
B19: 46103 | C19: Received from Sana Mart | E19: 12000 | G19: 46090 | H19: Freight inward paid | I19: 4500
B20: 46107 | C20: Cash sales | D20: 365000 | G20: 46094 | H20: Paid salaries | I20: 30000
B21: 46108 | C21: Customer paid by bank transfer | E21: 12000 | G21: 46095 | H21: Shop supplies purchased | I21: 6800
B22: 46111 | C22: Received from Bilal Stores | E22: 9000 | G22: 46096 | H22: Paid Ahmed Traders | I22: 20000
G23: 46098 | H23: Customer returned goods | I23: 3000
G24: 46100 | H24: Water bill paid | I24: 3200
G25: 46102 | H25: Advertising paid | J25: 9000
G26: 46104 | H26: Owner withdrew for personal use | I26: 10000
G27: 46105 | H27: Telephone and internet paid | I27: 5500
G28: 46106 | H28: Paid Noor Wholesalers | I28: 15000
G29: 46109 | H29: Paid delivery expense | J29: 4000
G30: 46110 | H30: Purchased goods | I30: 28000
C35: FOOTING | D35: =SUBTOTAL(109,D13:D34) -> 947000 | E35: =SUBTOTAL(109,E13:E34) -> 100000 | H35: FOOTING | I35: =SUBTOTAL(109,I13:I34) -> 360500 | J35: =SUBTOTAL(109,J13:J34) -> 13000
G36: 46112 | H36: CLOSING BALANCES CARRIED FORWARD | I36: =D35-I35 -> 586500 | J36: =E35-J35 -> 87000

Sheet DATA_FOR_BANK_RECONCILIATION
A2: BANK BOOK | G2: BANK STATEMENT
A5: Date | B5: Description / Particulars | C5: Debit (Receipts) PKR | D5: Credit (Payments) PKR | E5: Balance PKR | G5: Date | H5: Description / Particulars | I5: Debit (Payements) PKR | J5: Credit (Receipts) PKR | K5: Balance PKR
A7: 46082 | B7: Opening Balance (as per Ledger) | C7: - | D7: - | E7: 0 | G7: 46082 | H7: Opening Balance (as per bank statement) | K7: 0
A9: 46088 | B9: Received from Bilal Stores | C9: 25000 | E9: =E7+C9-D9 -> 25000 | G9: 46088 | H9: Deposit from Bilal Stores | J9: 25000 | K9: =K7+J9-I9 -> 25000
A10: 46093 | B10: Received from Sana Mart | C10: 18000 | E10: =E9+C10-D10 -> 43000 | G10: 46093 | H10: Deposit from Sana Mart | J10: 18000 | K10: =K9+J10-I10 -> 43000
A11: 46099 | B11: Received from Bilal Stores | C11: 24000 | E11: =E10+C11-D11 -> 67000 | G11: 46099 | H11: Deposit from Bilal Stores | J11: 24000 | K11: =K10+J11-I11 -> 67000
A12: 46102 | B12: Advertising paid | D12: 9000 | E12: =E11+C12-D12 -> 58000 | G12: 46099 | H12: Dishonoured Cheque | I12: 24000 | K12: =K11+J12-I12 -> 43000
A13: 46103 | B13: Cheque received from Sana Mart | C13: 12000 | E13: =E12+C13-D13 -> 70000 | G13: 46102 | H13: Advertising cheque | I13: 9000 | K13: =K12+J13-I13 -> 34000
A14: 46108 | B14: Customer paid by cheque | C14: 12000 | E14: =E13+C14-D14 -> 82000 | G14: 46110 | H14: Bank service charges | I14: 500 | K14: =K13+J14-I14 -> 33500
A15: 46109 | B15: Paid delivery expense | D15: 4000 | E15: =E14+C15+-D15 -> 78000 | G15: 46112 | H15: Bank profit/interest credited | J15: 300 | K15: =K14+J15-I15 -> 33800
A16: 46111 | B16: Received from Bilal Stores | C16: 9000 | E16: =+E15+C16-D16 -> 87000 | K16: Closing Balance
E17: Closing Balance

Sheet BANK RECONCILIATION
A1: WS COMPANY
A2: Bank Reconcilation Report
A3: FOR THE MONTH ENDED MARCH, 2026
A5: Description | B5: Date | C5: Cheque # | E5: Amount PKR
A8: Closing Balance as per General Ledger Book | E8: ='CASH BOOK'!J36 -> 87000
A11: Items in bank statement but not in bank book
A13: Dishonoured Cheque | B13: 46099 | E13: -24000
A14: Bank service charges | B14: 46110 | E14: -500
A15: Bank profit/interest credited | B15: 46112 | E15: 300
E16: =SUM(E13:E15) -> -24200
A20: Items in Bank Book but not in bank Statement
A22: Less:Outstanding Lodgments
A23: Received from Sana Mart | B23: 46103 | E23: -12000
A24: Customer paid by cheque | B24: 46108 | E24: -12000
A25: Received from Bilal Stores | B25: 46111 | E25: -9000
E26: =SUM(E23:E25) -> -33000
A28: Add:Unpresented Cheques
A29: Paid delivery expense | B29: 46109 | E29: 4000
E30: =E29 -> 4000
A34: Closing Balance as per bank Statement | E34: =E8+E16+E26+E30 -> 33800

Sheet INCOME STATEMENT
B9: Sales | F9: ='TRIAL BALANCE'!D27 -> 780000
B10: Sales Return | F10: =-'TRIAL BALANCE'!C28 -> -3000
B11: NET SALES | G11: =SUM(F9:F10) -> 777000
B13: Openinng inventory
B14: Cost of sales | F14: =-'TRIAL BALANCE'!C22 -> -225000
B15: Inventory return | F15: ='TRIAL BALANCE'!D32 -> 5000
B16: Closing inventory | F16: 11400 | G16: =SUM(F13:F16) -> -208600
B17: GROSS PROFIT | G17: =SUM(G11:G16) -> 568400
B19: OPERATING PROFIT
B20: Rent | F20: ='GENERAL LEDGER'!F26 -> 40000
B21: Electricity | F21: ='GENERAL LEDGER'!F20 -> 12500
B22: Telephone and Internet | F22: ='GENERAL LEDGER'!F32 -> 5500
B23: Frieght | F23: ='GENERAL LEDGER'!F21 -> 4500
B24: Salaries | F24: ='GENERAL LEDGER'!F27 -> 30000
B25: Water | F25: ='GENERAL LEDGER'!F33 -> 3200
B26: Advertisment | F26: ='GENERAL LEDGER'!F11 -> 9000
B27: Delivery | F27: ='GENERAL LEDGER'!F18 -> 4000
B28: Depreciation | F28: ='GENERAL LEDGER'!F19 -> 1500
B29: TOTAL OPERATING PROFIT | G29: =-SUM(F20:F28) -> -110200
B30: Finance cost | G30: 0
B31: Tax | G31: 0
B32: NET PROFIT | G32: =SUM(G17,G29:G30,G31) -> 458200
L36: =UPPER('BALANCE SHEET'!I30)

Sheet BALANCE SHEET
B9: ASSETS
B10: CURRENT ASSETS
B11: CASH | E11: ='GENERAL LEDGER'!F17 -> 586500
B12: BANK | E12: ='GENERAL LEDGER'!F14 -> 87000
B13: ACCOUNTS RECEIVABLE | E13: ='GENERAL LEDGER'!F10+'GENERAL LEDGER'!F12+'GENERAL LEDGER'!F15+'GENERAL LEDGER'!F30 -> 308000
B14: SUPPLIES | E14: ='GENERAL LEDGER'!F33 -> 3200
B16: FIXED ASSETS
B17: OFFICE FURNITURE | D17: ='GENERAL LEDGER'!F25 -> 55000
B18: ALLOWNCE FOR DEPRECIATION - OFFICE FURNITURE | D18: ='GENERAL LEDGER'!F13 -> -1500 | E18: =SUM(D17:D18) -> 53500
B20: TOTAL ASSETS | E20: =SUM(E11:E18) -> 1038200
B23: LIABILITIES
B24: CURRENT LIABILITIES
B25: ACCOUNTS PAYABLE | E25: ='GENERAL LEDGER'!F26 -> 40000
B27: LONG-TERM LIABILITIES
B29: TOTAL LIABILITIES | E29: =E25 -> 40000
B31: OWNERS EQUITY | K31: =UPPER(I31)
B32: CONTRIBUTED CAPITAL | E32: ='GENERAL LEDGER'!E16 -> 550000 | K32: =UPPER(I32)
B33: DRAWINGS | E33: -10000 | K33: =UPPER(I33)
B34: PROFIT / (LOSS) | E34: ='INCOME STATEMENT'!G32 -> 458200 | K34: =UPPER(I34)
K35: =UPPER(I35)
B36: TOTAL OWNERS EQUITY | E36: =SUM(E32:E34) -> 998200 | K36: =UPPER(I36)
I37: =UPPER(G37) | K37: =UPPER(I37)
B38: TOTAL LIABILITIES AND EQUITIES | E38: =SUM(E36,E29) -> 1038200 | I38: =UPPER(G38) | K38: =UPPER(I38)
I39: =UPPER(G39) | K39: =UPPER(I39)
I40: =UPPER(G40) | K40: =UPPER(I40)
F45: =UPPER(D45)
